Workbook

Sheet Ginning Mill 
B1: Detail Ginning Mills Labor Colony
C2: Ground Floor
B3: S.No | C3: Quarter No. | D3: No of Persons | E3: Occupied by
B4: 1 | C4: 1 | D4: 15 | E4: Lajbhar’s Labor
B5: 2 | C5: 2 | D5: 4 | E5: Security
B6: 3 | C6: 3 | D6: 3 | E6: Fire Staff
B7: 4 | C7: 4 | D7: 3 | E7: Gadoon Knitting (Contractor)
B8: 5 | C8: 5 | D8: 8 | E8: Gadoon Knitting (Contractor)
B9: 6 | C9: 6 | D9: 6 | E9: Main Lab
B10: 7 | C10: 7 | D10: 7 | E10: Cotton Labor
B11: 8 | C11: 8 | D11: 8 | E11: Cotton Labor
B12: 9 | C12: 9 | D12: 3 | E12: Lifter Driver
B14: Detail Ginning Mills Labor Colony
C15: First Floor
B16: S.No | C16: Quarter No. | D16: No of Persons | E16: Occupied by
B17: 1 | C17: 101 | D17: 8 | E17: Gadoon Knitting (Contractor)
B18: 2 | C18: 102 | D18: 9 | E18: Gadoon Knitting (Contractor)
B19: 3 | C19: 103 | D19: 8 | E19: Gadoon Knitting (Contractor)
B20: 4 | C20: 104 | D20: 9 | E20: Gadoon Knitting (Contractor)
B21: 5 | C21: 105 | D21: 8 | E21: Gadoon Knitting (Contractor)
B22: 6 | C22: 106 | D22: 9 | E22: Gadoon Knitting (Contractor)
B23: 7 | C23: 107 | D23: 8 | E23: Gadoon Knitting (Contractor)
B24: 8 | C24: 108 | D24: 8 | E24: Gadoon Knitting (Contractor)
B25: 9 | C25: 109 | D25: 13 | E25: Lajbhar’s Labor

Sheet Officer Family Block
B1: Detail Officers Family Block/Bungalow’s No.1 Ground Floor
B4: S.No | C4: Quarter No. | D4: Name | E4: Designation | F4: No of Persons | G4: Remarks
B5: 1 | C5: 1 | D5: Syed Asim Raza | E5: G.M K.P.1 | F5: 7 | G5: Family
B6: 2 | C6: 2 | D6: Khurram Junaid | E6: Sr. G.M Main Lab | F6: 5 | G6: Family
B7: 3 | C7: 3 | D7: Khalid Zahoor | E7: Sr. G.M K.P.3 | F7: 4 | G7: Family
B9: Detail Officers Family Block No.2 Ground Floor
B12: 4 | C12: 1 | D12: Adeel Shahid | E12: P.A E. D Sb | F12: 6 | G12: Family
B13: 5 | C13: 2 | D13: Adil Kayani | E13: Asst P. A ED Sb | F13: 5 | G13: Family
B15: First Floor
B17: 6 | C17: 101 | D17: Tahir Nawaz | E17: Utility Manager | F17: 7 | G17: Family
B18: 7 | C18: 102 | D18: Umar Hayat | E18: Lucky Energy | F18: 5 | G18: Family
B20: Second Floor
B22: 8 | C22: 201 | D22: Azhar | E22: Utility Manager | F22: 9 | G22: Family
B23: 9 | C23: 202 | D23: Hamid Randhawa | E23: Sr. T.M K.P.3 | F23: 7 | G23: Family
B25: Detail Officers Family Block No.3 Ground Floor
B28: 10 | C28: 1 | D28: Rizwan Yaqoob | E28: Sr. T.M K.P.2 | F28: 5 | G28: Family
B29: 11 | C29: 2 | D29: Athar | E29: Lucky Knits | F29: 5 | G29: Family
B31: First Floor
B33: 12 | C33: 101 | D33: Mudassir | E33: T.M K.P.1 | F33: 7 | G33: Family
B34: 13 | C34: 102 | D34: Sohail | E34: Sr. T.M K.P.4 | F34: 5 | G34: Family
B36: Second Floor
B38: 14 | C38: 201 | D38: Kashif Awan | E38: G.M Main Lab | F38: 7 | G38: Family
B39: 15 | C39: 202 | D39: Atif Arshad | E39: Sr. G.M K.P.2 | F39: 5 | G39: Family
B41: Detail Officers Family Block No.4 Ground Floor
B44: 16 | C44: 1 | D44: Amjad | E44: Lucky Knits | F44: 6 | G44: Family
B45: 17 | C45: 2 | D45: Daniyal | E45: Gadoon Dyeing | F45: 7 | G45: Family
B47: First Floor
B49: 18 | C49: 101 | D49: Mazhar Iqbal | E49: P.M K.P.3 | F49: 5 | G49: Family
B50: 19 | C50: 102 | D50: Late Gulzar | E50: P.M K.P.1 | F50: 7 | G50: Family
B52: Second Floor
B54: 20 | C54: 201 | D54: Saeed | E54: P.I K.P.2 | F54: 6 | G54: Family
B55: 21 | C55: 202 | D55: Azeem | E55: Gadoon Dyeing | F55: 6 | G55: Family

Sheet Single Room Family Block
B1: Detail Single Bed Room Family Block No.1 S Ground Floor
C4: Quarter No. | D4: Name | E4: Designation | F4: Depart | G4: No of Persons | H4: Mill No. | I4: Remarks
B5: 1 | C5: S-01 | D5: Shahid | E5: Jaber | F5: Ring | G5: 4 | H5: K.P.2 | I5: Family
B6: 2 | C6: S-02 | D6: Hakim | E6: Clerk | F6: Main Lab | G6: 6 | H6: G. Mills | I6: Family
B7: 3 | C7: S-03 | D7: Asif | E7: Pcking Incharge | F7: Packing | G7: 4 | H7: K.P.1 | I7: Family
B8: 4 | C8: S-04 | D8: Arif | E8: Jaber | F8: Ring | G8: 8 | H8: K.P.1 | I8: Family
B9: 5 | C9: S-05 | D9: Sharafaq | E9: Operator | F9: MVS | G9: 4 | H9: G. Mills | I9: Family
B10: 6 | C10: S-06 | D10: Abbas | E10: Jaber | F10: Carding | G10: 5 | H10: K.P.3 | I10: Family
B11: 7 | C11: S-07 | D11: Javed | E11: Operator | F11: Ring | G11: 7 | H11: K.P.3 | I11: Family
B12: 8 | C12: S-08 | D12: Yousuf | E12: Operator | F12: Ring | G12: 8 | H12: K.P.3 | I12: Family
B13: 9 | C13: S-09 | D13: Nadeem | E13: Packing Jaber | F13: Contractor Haji Rab Nawaz | G13: 9 | H13: K.P.1 | I13: Family
B14: 10 | C14: S-10 | D14: Muhammad Azam | E14: Clerk | F14: Main Laboratory | G14: 9 | H14: G. Mills | I14: Family
B15: 11 | C15: S-11 | D15: Talib Hussain | E15: Driver | F15: Driver | G15: 5 | H15: K.P.3 | I15: Family
B16: 12 | C16: S-12 | D16: Sabir Ali | E16: Operator | F16: Ring | G16: 5 | H16: K.P.1 | I16: Family
B18: Detail Single Bed Room Family Block No.1 S First Floor
B21: 13 | C21: S-101 | D21: Waqar | E21: Assistant Foreman | F21: Electric | G21: 6 | H21: K.P.1 | I21: Family
B22: 14 | C22: S-102 | D22: Muhammad Hanif | E22: Operator | F22: Ring | G22: 5 | H22: K.P.1 | I22: Family
B23: 15 | C23: S-103 | D23: Saif ur rehman | E23: Driver | F23: Diver | G23: 2 | H23: K.P.2 | I23: Family
B24: 16 | C24: S-104 | D24: Shafiq Ahmed | E24: Jaber | F24: Auto Cone | G24: 5 | H24: K.P.2 | I24: Family
B25: 17 | C25: S-105 | D25: Muhammad Munawar | E25: Jaber | F25: D/S | G25: 6 | H25: K.P.3 | I25: Family
B26: 18 | C26: S-106 | D26: Umar Hayat | E26: Assistant Foreman | F26: A/C | G26: 6 | H26: K.P.1 | I26: Family
B27: 19 | C27: S-107 | D27: Abdul Nabi | E27: Operator | F27: Ring | G27: 5 | H27: K.P.1 | I27: Family
B28: 20 | C28: S-108 | D28: Mashooq Ali | E28: Operator | F28: Ring | G28: 7 | H28: K.P.1 | I28: Family
B29: 21 | C29: S-109 | D29: Muhammad Asif | E29: Assistant Foreman | F29: D.S | G29: 2 | H29: K.P.1 | I29: Family
B30: 22 | C30: S-110 | D30: Bashir | E30: Jaber | F30: Auto Cone | G30: 2 | H30: K.P.1 | I30: Bachelor
B31: 23 | C31: S-111 | D31: Ashraf | E31: Jaber | F31: Carding | G31: 6 | H31: K.P.3 | I31: Family
B32: 24 | C32: S-112 | D32: M.Ismail | E32: Jaber | F32: Ring | G32: 5 | H32: K.P.2 | I32: Family
B34: Detail Single Bed Room Family Block No.1 S Second Floor
C37: S-201 | D37: M.Abubakar | E37: Assistant Foreman | F37: Blow Room | G37: 4 | H37: K.P.2 | I37: Family
B38: 26 | C38: S-202 | D38: Muhammad Asif | E38: Operator | F38: Auto Cone | G38: 3 | H38: K.P.1 | I38: Family
B39: 27 | C39: S-203 | D39: Luqman | E39: Foreman | F39: Blow Room | G39: 4 | H39: K.P.1 | I39: Family
B40: 28 | C40: S-204 | D40: Jaleel Ahmad Waqar | E40: Jaber | F40: Ring | G40: 5 | H40: K.P.1 | I40: Family
B41: 29 | C41: S-205 | D41: Nadeem | E41: Operator | F41: Ring | G41: 6 | H41: K.P.1 | I41: Family
B42: 30 | C42: S-206 | D42: Shaukat | E42: Jaber | F42: Back Press | G42: 6 | H42: K.P.1 | I42: Family
B43: 31 | C43: S-207 | D43: Umar Ijaz | E43: Assist Foreman | F43: Carding | G43: 5 | H43: K.P.1 | I43: Family
B44: 32 | C44: S-208 | D44: Ali Haider | E44: Jaber | F44: Blow Room Press Contractor Nazim | G44: 7 | H44: Press, Blow Room K.P.1 | I44: Family
B45: 33 | C45: S-209 | D45: Muhammad Jameel | E45: Assist Foreman | F45: Ring | G45: 1 | H45: K.P.1 | I45: Bachelor
B46: 34 | C46: S-210 | D46: Muneer | E46: Assist Foreman | F46: Auto Cone | G46: 7 | H46: K.P.1 | I46: Family
B47: 35 | C47: S-211 | D47: Sajid | E47: Jaber | F47: Carding | G47: 5 | H47: K.P.1 | I47: Family
B48: 36 | C48: S-212 | D48: Younis | E48: Fitter | F48: Main Workshop | G48: 5 | H48: G. Mills | I48: Family
...

Sheet Detail Two Room Family Block
B1: Detail Two Bed Room Family Block No.1 D Ground Floor
C4: Quarter No. | D4: Name | E4: Designation | F4: Depart | G4: Mill No. | H4: No of Persons | I4: Remarks
B5: 1 | C5: D-01 | D5: Fiyaz | E5: Foreman | F5: Ring | G5: K.P.1 | H5: 5 | I5: Bachelor
B6: 2 | C6: D-02 | D6: Asrar | E6: Foreman | F6: A/C | G6: K.P.1 | H6: 4 | I6: Family
B7: 3 | C7: D-03 | D7: Fazal Dad | E7: Head Jaber | F7: Auto cone | G7: K.P.1+2 | H7: 6 | I7: Bachelor
B8: 4 | C8: D-04 | D8: Anwar Qaisar | E8: Foreman | F8: Auto cone | G8: K.P.1 | H8: 8 | I8: Family
B10: Detail Two Bed Room Family Block No.1 D First Floor
B13: 5 | C13: D-101 | D13: Gulzar | E13: Engineer | F13: Blow Room | G13: K.P.3 | H13: 3 | I13: Bachelor
B14: 6 | C14: D-102 | D14: Amjad | E14: Foreman | F14: Ring | G14: K.P.3 | H14: 3 | I14: Bachelor
B15: 7 | C15: D-103 | D15: Ramzan | E15: Foreman | F15: M.V. S | G15: K.P.5 | H15: 3 | I15: Family
B16: 8 | C16: D-104 | D16: Azam | E16: A. Foreman | F16: Main Workshop | G16: General Mills | H16: 4 | I16: Family
B18: Detail Two Bed Room Family Block No.1 D Second Floor
B21: 9 | C21: D-201 | D21: Altaf | E21: Engineer | F21: Electric | G21: K.P.1 | H21: 7 | I21: Family
B22: 10 | C22: D-202 | D22: Nazeer | E22: Foreman | F22: M. V. S | G22: K.P.5 | H22: 5 | I22: Family
B23: 11 | C23: D-203 | D23: Hameed Shah | E23: Foreman | F23: Blow Room | G23: K.P.2 | H23: 5 | I23: Family
B24: 12 | C24: D-204 | D24: Abid | E24: Head Jaber | F24: Back press | G24: K.P.1 | H24: 4 | I24: Family
B26: Detail Two Bed Room Family Block No.1 D Third Floor
B29: 13 | C29: D-301 | D29: Ahmed Qureshi | E29: Foreman | F29: Shop R/C | G29: K.P.2 | H29: 4 | I29: Family
B30: 14 | C30: D-302 | D30: Asif | E30: Foreman | F30: Ring | G30: K.P.2 | H30: 7 | I30: Family
B31: 15 | C31: D-303 | D31: Asif | E31: Foreman | F31: Carding | G31: K.P.1 | H31: 4 | I31: Family
B32: 16 | C32: D-304 | D32: Arif | E32: Head Clerk | F32: E. D Office | G32: General Mills | I32: Family
B34: Detail Two Bed Room Family Block No.2 D Ground Floor
C37: Quarter No. | D37: Name | E37: Designation | F37: Depart | G37: Mill No. | H37: No of Persons | I37: Remarks
B38: 1 | C38: D-01 | D38: Foreman Mess
B39: 2 | C39: D-02 | D39: Muhammad Arshad | E39: Foreman | F39: Comber | G39: K.P.2 | H39: 5 | I39: Family
B40: 3 | C40: D-03 | D40: Faqeer Muhammad | E40: Engineer | F40: Auto cone | G40: K.P.2 | H40: 6 | I40: Family
B41: 4 | C41: D-04 | D41: Muhammad Iqbal | E41: Foreman | F41: A/C | G41: K.P.2 | H41: 7 | I41: Family
B43: Detail Two Bed Room Family Block No.2 D First Floor
B46: 5 | C46: D-101 | D46: Hafeez | E46: H/ Jaber | F46: Back press | G46: K.P.2 | H46: 8 | I46: Family
B47: 6 | C47: D-102 | D47: Nadeem Lau | E47: Foreman | F47: Auto cone | G47: K.P.2 | H47: 7 | I47: Family
B48: 7 | C48: D-103 | D48: Naveed | E48: Foreman | F48: Drying Simplex | G48: K.P.3 | H48: 6 | I48: Family
B49: 8 | C49: D-104 | D49: Muhammad Ramzan | E49: Foreman | F49: Electric | G49: K.P.2 | H49: 7 | I49: Family
B51: Detail Two Bed Room Family Block No.2 D Second Floor
B54: 9 | C54: D-201 | D54: Zahid | E54: Foreman | F54: Carding | G54: K.P.2 | H54: 5 | I54: Family
B55: 10 | C55: D-202 | D55: Imran | E55: Foreman | F55: Drying Simplex | G55: K.P.2 | H55: 6 | I55: Family
B56: 11 | C56: D-203 | D56: Noman | E56: Foreman | F56: A/C | G56: General Mills | H56: 4 | I56: Family
B57: 12 | C57: D-204 | D57: Rab Nawaz | E57: H/Jaber | F57: Ring | G57: K.P.2 | H57: 7 | I57: Family
B59: Detail Two Bed Room Family Block No.2 D Third Floor
B62: 13 | C62: D-301 | D62: Rajab | E62: H/Jaber | F62: Ring | G62: K.P.3 | H62: 6 | I62: Family
B63: 14 | C63: D-302 | D63: Abdul Waheed | E63: Foreman | F63: Electric | G63: K.P.3 | H63: 7 | I63: Family
...

Sheet Admin Family Block
A1: Security Admin Family Block Ground Floor
B4: Quarter No. | C4: Name | D4: Designation | E4: Depart | F4: No of Persons | G4: Remarks
A5: 1 | B5: A | C5: Shahbaz | D5: Watchman | E5: Security | F5: 5 | G5: Bachelor
A6: 2 | B6: B | C6: Abdul Hameed | D6: Head Watchman | E6: Security | F6: 5 | G6: Family
A7: 3 | B7: C | C7: Ahmed | D7: Peon | E7: Admin | F7: 7 | G7: Bachelor
A8: 4 | B8: D | C8: Amir | D8: SHOP | E8: Outsider | F8: 2 | G8: Family
A10: Security Admin Family Block First Floor
A13: 5 | B13: E | C13: Ashfaq | D13: Clerk | E13: Cotton | F13: 5 | G13: Family
A14: 6 | B14: F | C14: Shoaib | D14: Mechanic | E14: Mechanical Dept. | F14: 8 | G14: Family
A15: 7 | B15: G | C15: Basheer | D15: Head Watchman | E15: Security | F15: 4 | G15: Family
A16: 8 | B16: H | C16: Zaffar Hussain | D16: (Late) Qurantine Incharge | E16: Admin | F16: 5 | G16: Family

Sheet Admin Bachelor Block
A1: Security Admin Bachelor Block Ground Floor
B4: Quarter No. | C4: Name | D4: Designation | E4: Depart | F4: No of Persons | G4: Remarks
A5: 1 | B5: A | C5: Tahir Khan | D5: Sr. Manager Admin | E5: Admin | F5: 1 | G5: Bachelor
A6: 2 | B6: B | C6: Khalid Jhokio | D6: D.M Admin | E6: Admin | F6: 1 | G6: Bachelor
A7: 3 | B7: C | C7: Nabeel/Ismail | D7: AM Admin/Admin Officer | E7: Admin | F7: 2 | G7: Bachelor
A8: 4 | B8: D | C8: Irfan Baig | D8: Cotton Incharge | E8: Admin | F8: 1 | G8: Bachelor
A9: 5 | B9: E | C9: Wajid Ibrar | D9: Head Watchman | E9: Admin | F9: 3 | G9: Bachelor
A10: 6 | B10: F | C10: Saab Dino | D10: Head Watchman | E10: Admin | F10: 4 | G10: Bachelor
A11: 7 | B11: G | C11: M.Imran | D11: Maintenance Incharge | E11: Admin | F11: 3 | G11: Bachelor
A12: 8 | B12: H | C12: Zartaj | D12: Driver | E12: Admin | F12: 4 | G12: Bachelor
B13: I | C13: Rashid | D13: Head Watchman | E13: Admin | F13: 5 | G13: Bachelor
B14: J | C14: Riaz | D14: Time keeper | E14: Time Office | F14: 2 | G14: Bachelor

Sheet Shop & Hotel Workers Data
A1: COMPANY COLONY – SHOPS & HOTELS WORKERS DATA
A3: S. No. | B3: Shop / Hotel Name | C3: Shop Incharge | D3: Worker Name | E3: CNIC No. | F3: Address
A4: 1 | B4: Hotel No.1 | C4: Arshad Ali | D4: Arshad Ali | E4: Not Available | F4: Labour Colony
A5: 2 | B5: Hotel No.1 | C5: Arshad Ali | D5: Sajjad Amjad | E5: 34201-3658077-3 | F5: Labour Colony
A6: 3 | B6: Hotel No.1 | C6: Arshad Ali | D6: Iqbal | E6: 42201-41198967 | F6: Labour Colony
A7: 4 | B7: Hotel No.1 | C7: Arshad Ali | D7: Naimat ullah | E7: 34201-4128178-9 | F7: Labour Colony
A8: 5 | B8: Hotel No.1 | C8: Arshad Ali | D8: Sami ullah | E8: 45303-9638133-3 | F8: Labour Colony
A9: 6 | B9: Hotel No.1 | C9: Arshad Ali | D9: Abu bakr | E9: Not Available | F9: Labour Colony
A10: 7 | B10: Hotel No.1 | C10: Arshad Ali | D10: Ali | E10: Not Available | F10: Labour Colony
A11: 8 | B11: Hotel No.1 | C11: Arshad Ali | D11: Sameer | E11: Not Available | F11: Labour Colony
A12: 9 | B12: Hotel No.2 | C12: Rana Shafeeq | D12: Basheer | E12: Not Available | F12: Labour Colony
A13: 10 | B13: Hotel No.2 | C13: Rana Shafeeq | D13: Shahzad | E13: Not Available | F13: Labour Colony
A14: 11 | B14: Hotel No.2 | C14: Rana Shafeeq | D14: Sameer | E14: Not Available | F14: Labour Colony
A15: 12 | B15: Hotel No.2 | C15: Rana Shafeeq | D15: Nadeem | E15: 3120109372325 | F15: Labour Colony
A16: 13 | B16: Hotel No.2 | C16: Rana Shafeeq | D16: Shoaib | E16: 3130302714881 | F16: Labour Colony
A17: 14 | B17: Hotel No.2 | C17: Rana Shafeeq | D17: Tariq | E17: 3120151162807 | F17: Labour Colony
A18: 15 | B18: Hotel No.2 | C18: Rana Shafeeq | D18: Usman | E18: 3130315459063 | F18: Labour Colony
A19: 16 | B19: Hotel No.2 | C19: Rana Shafeeq | D19: Bilal | E19: 425014490557 | F19: Labour Colony
A20: 17 | B20: Hotel No.2 | C20: Rana Shafeeq | D20: Atiq | E20: 4250193103655 | F20: Labour Colony
A21: 18 | B21: Hotel No.2 | C21: Rana Shafeeq | D21: Ramzan | E21: 341033651448 | F21: Labour Colony
A22: 19 | B22: Hotel No.2 | C22: Rana Shafeeq | D22: Hamza | E22: 4250192058655 | F22: Labour Colony
A23: 20 | B23: Hotel No.2 | C23: Rana Shafeeq | D23: Ahsan | E23: Not Available | F23: Labour Colony
A24: 21 | B24: Hotel No.2 | C24: Rana Shafeeq | D24: Ahmed | E24: Not Available | F24: Labour Colony
A25: 22 | B25: Hotel No.2 | C25: Rana Shafeeq | D25: Sohail | E25: Not Available | F25: Labour Colony
A26: 23 | B26: Hotel No.2 | C26: Rana Shafeeq | D26: Rana Shafeeq | E26: 4250117038321 | F26: Labour Colony
A27: 24 | B27: Imran Hotel No.3 | C27: Imran | D27: Imran | E27: Not Available | F27: Labour Colony
A28: 25 | B28: Imran Hotel No.3 | C28: Imran | D28: Hassan | E28: Not Available | F28: Labour Colony
A29: 26 | B29: Imran Hotel No.3 | C29: Imran | D29: Sulaiman | E29: 44404-94770405 | F29: Labour Colony
A30: 27 | B30: Imran Hotel No.3 | C30: Imran | D30: Umer | E30: Not Available | F30: Labour Colony
A31: 28 | B31: Imran Hotel No.3 | C31: Imran | D31: Ateeq | E31: 44401-682714930 | F31: Labour Colony
A32: 29 | B32: Imran Hotel No.3 | C32: Imran | D32: Jan Muhammad | E32: 44301-70411123 | F32: Labour Colony
A33: 30 | B33: Imran Hotel No.3 | C33: Imran | D33: Lal Baksh | E33: 4404-84525011 | F33: Labour Colony
A34: 31 | B34: Imran Hotel No.3 | C34: Imran | D34: Waqas Ahmed | E34: 44401-90081387 | F34: Labour Colony
A35: 32 | B35: Imran Hotel No.3 | C35: Imran | D35: Anwar Ali | E35: 45208-07829259 | F35: Labour Colony
A36: 33 | B36: Imran Hotel No.3 | C36: Imran | D36: Parail | E36: 45208-18666781 | F36: Labour Colony
A37: 34 | B37: Imran Hotel No.3 | C37: Imran | D37: Asad Hussain | E37: 31303-57535245 | F37: Labour Colony
A38: 35 | B38: Imran Hotel No.3 | C38: Imran | D38: Rafiq | E38: 44301-26155643 | F38: Labour Colony
... A163: 160 | B163: Shop No.53 | C163: Ali Raza | D163: Ali Raza | E163: 42101-3160955-9 | F163: Labour Colony
E1048575: {=-A1048510-E102ds} -> #NAME?

Sheet Shop & Hotel Summary
A1: SHOP & HOTEL-WISE WORKERS SUMMARY
A3: S. No. | B3: Shop / Hotel Name | C3: Type | D3: Owner / Allottee Name | E3: Designation In Mill | F3: Total Workers | G3: Active Workers
A4: 1 | B4: Hotel No.1 | C4: Hotel | D4: Mazhar Iqbal | E4: Production Incharge (Mill-3) | F4: 8 | G4: 8
A5: 2 | B5: Hotel No.2 | C5: Hotel | D5: Saeed | E5: Production Incharge (Mill-2) | F5: 15 | G5: 15
A6: 3 | B6: Hotel No.3 | C6: Hotel | D6: Manzoor | E6: Head Jabar (Mill-1) | F6: 8 | G6: 8
A7: 4 | B7: Hotel No. 4 | C7: Hotel | D7: Jaleel | E7: Head Jabar (Mill-1) | F7: 19 | G7: 19
A8: 5 | B8: Shop No.1 | C8: Shop | D8: Adeel | E8: PA to ED Sahb | F8: 2 | G8: 2
A9: 6 | B9: Shop No.2 | C9: Shop | D9: Mazhar Iqbal | E9: Production Incharge (Mill-3) | F9: =IF(B8="","",COUNTIF('Shop & Hotel Workers Data'!B$4:B$102,B8)) -> 2 | G9: 2
A10: 7 | B10: Shop No.3 | C10: Shop | D10: Saeed | E10: Production Incharge (Mill-2) | F10: =IF(B9="","",COUNTIF('Shop & Hotel Workers Data'!B$4:B$102,B9)) -> 6 | G10: 6
A11: 8 | B11: Shop No.4,5 | C11: Shop | D11: Qasim | E11: Outsider | F11: =IF(B10="","",COUNTIF('Shop & Hotel Workers Data'!B$4:B$102,B10)) -> 4 | G11: 4
A12: 9 | B12: Shop No.6 | C12: Shop | D12: Bilal | E12: Outsider | F12: =IF(B11="","",COUNTIF('Shop & Hotel Workers Data'!B$4:B$102,B11)) -> 5 | G12: 5
A13: 10 | B13: Shop No.7 | C13: Shop | D13: Hafeez | E13: Head Jabar (Mill-2) | F13: =IF(B12="","",COUNTIF('Shop & Hotel Workers Data'!B$4:B$102,B12)) -> 3 | G13: 3
A14: 11 | B14: Shop No.8 | C14: Shop | D14: Saifullah | E14: Assistant Fitter (Mill-2) | F14: =IF(B13="","",COUNTIF('Shop & Hotel Workers Data'!B$4:B$102,B13)) -> 2 | G14: 2
A15: 12 | B15: Shop No.9 | C15: Shop | D15: Akbar | E15: Peon (ED Sahb) | F15: =IF(B14="","",COUNTIF('Shop & Hotel Workers Data'!B$4:B$102,B14)) -> 1 | G15: 1
A16: 13 | B16: Shop No.10 | C16: Shop | D16: Saeed | E16: Production Incharge (Mill-2) | F16: =IF(B15="","",COUNTIF('Shop & Hotel Workers Data'!B$4:B$102,B15)) -> 4 | G16: 4
A17: 14 | B17: Shop No.11 | C17: Shop | D17: Saeed | E17: Production Incharge (Mill-2) | F17: =IF(B16="","",COUNTIF('Shop & Hotel Workers Data'!B$4:B$102,B16)) -> 1 | G17: 1
A18: 15 | B18: Shop No.12,13 | C18: Shop | D18: Mazhar Iqbal | E18: Production Incharge (Mill-3) | F18: =IF(B17="","",COUNTIF('Shop & Hotel Workers Data'!B$4:B$102,B17)) -> 2 | G18: 2
A19: 16 | B19: Shop No.14,15 | C19: Shop | D19: Shahid | E19: Peon (Joya Sahb) | F19: =IF(B18="","",COUNTIF('Shop & Hotel Workers Data'!B$4:B$102,B18)) -> 3 | G19: 3
A20: 17 | B20: Shop No.16 | C20: Shop | D20: Shahid Khan | E20: Contractor Payo Khan | F20: =IF(B19="","",COUNTIF('Shop & Hotel Workers Data'!B$4:B$102,B19)) -> 4 | G20: 4
... A23: 20 | B23: Shop No.19 | C23: Shop | D23: Shahid | E23: Peon (Joya Sahb) | F23: =IF(B22="","",COUNTIF('Shop & Hotel Workers Data'!B$4:B$102,B22)) -> 2 | G23: 2
A24: 21 | B24: Shop No.20 | C24: Shop | D24: Rajab | E24: Head Jabar (Mill-3) | F24: 1 | G24: 1
A25: 22 | B25: Shop No.21 | C25: Shop | D25: Haji Ahmed | E25: Peon (Khurram Sahb) | F25: 4 | G25: 4
A26: 23 | B26: Shop No.22 | C26: Shop | D26: Fazal Daad | E26: Head Jabar (auto cone Mill-1) | F26: 3 | G26: 3
A27: 24 | B27: Shop No.23 | C27: Shop | D27: Zameer | E27: Peon(Asim Sahb) | F27: 3 | G27: 3
A28: 25 | B28: Shop No.24 | C28: Shop | D28: Manzoor | E28: Head Jabar (Mill-1) | F28: 3 | G28: 3
A29: 26 | B29: Shop No.25 | C29: Shop | D29: Haji Rab Nawaz | E29: Contractor | F29: 4 | G29: 4
A30: 27 | B30: Shop No.26 | C30: Shop | D30: Yaseen | E30: Outsider | F30: 1 | G30: 1
A31: 28 | B31: Shop No.27 | C31: Shop | D31: Manazir | E31: Outsider | F31: 1 | G31: 1
A32: 29 | B32: Shop No.28 | C32: Shop | D32: Zafar Hussain | E32: Haji Rab Nawaz (Contractor) | F32: 3 | G32: 3
A33: 30 | B33: Shop No.29 | C33: Shop | D33: Azam | E33: Driver (Khurram Sahb) | F33: 3 | G33: 3
A34: 31 | B34: Shop No.30 | C34: Shop | D34: Adil Kiyani | E34: PA to ED Sahb | F34: 2 | G34: 2
A35: 32 | B35: Shop No.31 | C35: Shop | D35: Khaleel | E35: Outsider | F35: 1 | G35: 1
... A50: 47 | B50: Shop No.53 | C50: Shop | D50: Ali Raza | E50: Peon (Joya Sahb) | F50: 1 | G50: 1
F52: =IF(B51="","",COUNTIF('Shop & Hotel Workers Data'!B$4:B$102,B51)) | G52: =IF(B51="","",COUNTIFS('Shop & Hotel Workers Data'!B$4:B$102,B51,'Shop & Hotel Workers Data'!#REF!,"Active"))
F53: =IF(B52="","",COUNTIF('Shop & Hotel Workers Data'!B$4:B$102,B52)) | G53: =IF(B52="","",COUNTIFS('Shop & Hotel Workers Data'!B$4:B$102,B52,'Shop & Hotel Workers Data'!#REF!,"Active"))
D55: TOTAL WORKERS | F55: =SUM(F4:F53) -> 153 | G55: =SUM(G4:G53) -> 153

Sheet Rent Detail
A1: For the Month of Aug-2026
A2: Shop No. | B2: Rent | C2: Shop No. | D2: Rent
A3: 1 | B3: 3000 | C3: 28 | D3: 2000
A4: 2 | B4: 2000 | C4: 29 | D4: 1000
A5: 3 | B5: 2000 | C5: 30 | D5: 2000
A6: 4 | B6: 3000 | C6: 31 | D6: 1000
A7: 5 | B7: 3000 | C7: 32 | D7: 2000
A8: 6 | B8: 1000 | C8: 33 | D8: 2000
A9: 7 | B9: 2000 | C9: 34 | D9: 2000
A10: 8 | B10: 2500 | C10: 35 | D10: Lucky Foods
A11: 9 | B11: 2000 | C11: 36 | D11: 5000
A12: 10 | B12: 1000 | C12: 37 | D12: 1000
A13: 11 | B13: 2000 | C13: 38 | D13: 2500
A14: 12 | B14: 2000 | C14: 39 | D14: 4000
A15: 13 | B15: 2000 | C15: 40 | D15: 1000
A16: 14 | B16: 3000 | C16: 41 | D16: 1000
A17: 15 | B17: 2000 | C17: 42 | D17: 1000
A18: 16 | B18: 2000 | C18: 43 | D18: 1000
A19: 17 | B19: 2000 | C19: 44 | D19: 2000
A20: 18 | B20: 2000 | C20: 45 | D20: 5000
A21: 19 | B21: 2000 | C21: 46 | D21: 5000
A22: 20 | B22: 2000 | C22: 47 | D22: 5000
... A28: 26 | B28: 1000 | C28: 53 | D28: 1000
A29: 27 | B29: 1000 | C29: 54
A30: Total > | B30: 55500 | C30: Total > | D30: 56500
A31: Grand Total | C31: =B30+D30 -> 112000
